


---------------------------------------------------------------------------------------------------------
11:09:36-2023-12-19-Не удалось получить текущую дату.
---------------------------------------------------------------------------------------------------------
Traceback (most recent call last):
  File "c:\Users\adamrv\Downloads\final-main\final-main\line.py", line 378, in main
    connect(1)
TypeError: connect() takes 0 positional arguments but 1 was given

During handling of the above exception, another exception occurred:

Traceback (most recent call last):
  File "c:\Users\adamrv\Downloads\final-main\final-main\error_functions.py", line 21, in error_line
    date = datetime.nows().strftime("%Y-%m-%d")
AttributeError: type object 'datetime.datetime' has no attribute 'nows'


---------------------------------------------------------------------------------------------------------






---------------------------------------------------------------------------------------------------------
11:17:17-2023-12-19-Не удалось получить текущую дату.
---------------------------------------------------------------------------------------------------------
Traceback (most recent call last):
  File "c:\Users\adamrv\Downloads\final-main\final-main\line.py", line 379, in main
    connect(1)
TypeError: connect() takes 0 positional arguments but 1 was given

During handling of the above exception, another exception occurred:

Traceback (most recent call last):
  File "c:\Users\adamrv\Downloads\final-main\final-main\error_functions.py", line 21, in error_line
    date = datetime.nows().strftime("%Y-%m-%d")
AttributeError: type object 'datetime.datetime' has no attribute 'nows'


---------------------------------------------------------------------------------------------------------






---------------------------------------------------------------------------------------------------------
11:48:53-2023-12-19- Не удалось передать JSON в функцию преобразования igra().
---------------------------------------------------------------------------------------------------------
Не удалось сформировать traceback. Ошибка обработчика исключений. line.py -> line 463

---------------------------------------------------------------------------------------------------------






---------------------------------------------------------------------------------------------------------
11:54:10-2023-12-19- Не удалось передать JSON в функцию преобразования igra().
---------------------------------------------------------------------------------------------------------
Не удалось сформировать traceback. Ошибка обработчика исключений. line.py -> line 463

---------------------------------------------------------------------------------------------------------






---------------------------------------------------------------------------------------------------------
15:14:00-2023-12-21- Не удалось получить id события > results_for_periods().Однако возникло исключение.
---------------------------------------------------------------------------------------------------------
Не удалось сформировать traceback. Ошибка обработчика исключений. parser_string.py -> line 27

---------------------------------------------------------------------------------------------------------






---------------------------------------------------------------------------------------------------------
15:14:00-2023-12-21- Не удалось получить id события > results_for_periods().Однако возникло исключение.
---------------------------------------------------------------------------------------------------------
Traceback (most recent call last):
  File "c:\Users\adamrv\Downloads\final-main\final-main\parser_string.py", line 17, in results_for_periods
    event = fact['event1']
KeyError: 'event1'


---------------------------------------------------------------------------------------------------------






---------------------------------------------------------------------------------------------------------
15:14:01-2023-12-21- Не удалось получить id события > results_for_periods().Однако возникло исключение.
---------------------------------------------------------------------------------------------------------
Traceback (most recent call last):
  File "c:\Users\adamrv\Downloads\final-main\final-main\parser_string.py", line 17, in results_for_periods
    event = fact['event1']
KeyError: 'event1'


---------------------------------------------------------------------------------------------------------






---------------------------------------------------------------------------------------------------------
15:14:01-2023-12-21- Не удалось получить id события > results_for_periods().Однако возникло исключение.
---------------------------------------------------------------------------------------------------------
Traceback (most recent call last):
  File "c:\Users\adamrv\Downloads\final-main\final-main\parser_string.py", line 17, in results_for_periods
    event = fact['event1']
KeyError: 'event1'


---------------------------------------------------------------------------------------------------------






---------------------------------------------------------------------------------------------------------
15:14:01-2023-12-21- Не удалось получить id события > results_for_periods().Однако возникло исключение.
---------------------------------------------------------------------------------------------------------
Traceback (most recent call last):
  File "c:\Users\adamrv\Downloads\final-main\final-main\parser_string.py", line 17, in results_for_periods
    event = fact['event1']
KeyError: 'event1'


---------------------------------------------------------------------------------------------------------






---------------------------------------------------------------------------------------------------------
15:14:02-2023-12-21- Не удалось получить id события > results_for_periods().Однако возникло исключение.
---------------------------------------------------------------------------------------------------------
Traceback (most recent call last):
  File "c:\Users\adamrv\Downloads\final-main\final-main\parser_string.py", line 17, in results_for_periods
    event = fact['event1']
KeyError: 'event1'


---------------------------------------------------------------------------------------------------------






---------------------------------------------------------------------------------------------------------
15:14:02-2023-12-21- Не удалось получить id события > results_for_periods().Однако возникло исключение.
---------------------------------------------------------------------------------------------------------
Traceback (most recent call last):
  File "c:\Users\adamrv\Downloads\final-main\final-main\parser_string.py", line 17, in results_for_periods
    event = fact['event1']
KeyError: 'event1'


---------------------------------------------------------------------------------------------------------






---------------------------------------------------------------------------------------------------------
15:14:03-2023-12-21- Не удалось получить id события > results_for_periods().Однако возникло исключение.
---------------------------------------------------------------------------------------------------------
Traceback (most recent call last):
  File "c:\Users\adamrv\Downloads\final-main\final-main\parser_string.py", line 17, in results_for_periods
    event = fact['event1']
KeyError: 'event1'


---------------------------------------------------------------------------------------------------------






---------------------------------------------------------------------------------------------------------
15:14:03-2023-12-21- Не удалось получить id события > results_for_periods().Однако возникло исключение.
---------------------------------------------------------------------------------------------------------
Traceback (most recent call last):
  File "c:\Users\adamrv\Downloads\final-main\final-main\parser_string.py", line 17, in results_for_periods
    event = fact['event1']
KeyError: 'event1'


---------------------------------------------------------------------------------------------------------






---------------------------------------------------------------------------------------------------------
15:14:04-2023-12-21- Не удалось получить id события > results_for_periods().Однако возникло исключение.
---------------------------------------------------------------------------------------------------------
Traceback (most recent call last):
  File "c:\Users\adamrv\Downloads\final-main\final-main\parser_string.py", line 17, in results_for_periods
    event = fact['event1']
KeyError: 'event1'


---------------------------------------------------------------------------------------------------------






---------------------------------------------------------------------------------------------------------
15:14:04-2023-12-21- Не удалось получить id события > results_for_periods().Однако возникло исключение.
---------------------------------------------------------------------------------------------------------
Traceback (most recent call last):
  File "c:\Users\adamrv\Downloads\final-main\final-main\parser_string.py", line 17, in results_for_periods
    event = fact['event1']
KeyError: 'event1'


---------------------------------------------------------------------------------------------------------






---------------------------------------------------------------------------------------------------------
15:14:04-2023-12-21- Не удалось получить id события > results_for_periods().Однако возникло исключение.
---------------------------------------------------------------------------------------------------------
Traceback (most recent call last):
  File "c:\Users\adamrv\Downloads\final-main\final-main\parser_string.py", line 17, in results_for_periods
    event = fact['event1']
KeyError: 'event1'


---------------------------------------------------------------------------------------------------------






---------------------------------------------------------------------------------------------------------
15:14:05-2023-12-21- Не удалось получить id события > results_for_periods().Однако возникло исключение.
---------------------------------------------------------------------------------------------------------
Traceback (most recent call last):
  File "c:\Users\adamrv\Downloads\final-main\final-main\parser_string.py", line 17, in results_for_periods
    event = fact['event1']
KeyError: 'event1'


---------------------------------------------------------------------------------------------------------






---------------------------------------------------------------------------------------------------------
15:14:05-2023-12-21- Не удалось получить id события > results_for_periods().Однако возникло исключение.
---------------------------------------------------------------------------------------------------------
Traceback (most recent call last):
  File "c:\Users\adamrv\Downloads\final-main\final-main\parser_string.py", line 17, in results_for_periods
    event = fact['event1']
KeyError: 'event1'


---------------------------------------------------------------------------------------------------------






---------------------------------------------------------------------------------------------------------
15:14:05-2023-12-21- Не удалось получить id события > results_for_periods().Однако возникло исключение.
---------------------------------------------------------------------------------------------------------
Traceback (most recent call last):
  File "c:\Users\adamrv\Downloads\final-main\final-main\parser_string.py", line 17, in results_for_periods
    event = fact['event1']
KeyError: 'event1'


---------------------------------------------------------------------------------------------------------






---------------------------------------------------------------------------------------------------------
15:14:06-2023-12-21- Не удалось получить id события > results_for_periods().Однако возникло исключение.
---------------------------------------------------------------------------------------------------------
Traceback (most recent call last):
  File "c:\Users\adamrv\Downloads\final-main\final-main\parser_string.py", line 17, in results_for_periods
    event = fact['event1']
KeyError: 'event1'


---------------------------------------------------------------------------------------------------------






---------------------------------------------------------------------------------------------------------
15:14:06-2023-12-21- Не удалось получить id события > results_for_periods().Однако возникло исключение.
---------------------------------------------------------------------------------------------------------
Traceback (most recent call last):
  File "c:\Users\adamrv\Downloads\final-main\final-main\parser_string.py", line 17, in results_for_periods
    event = fact['event1']
KeyError: 'event1'


---------------------------------------------------------------------------------------------------------






---------------------------------------------------------------------------------------------------------
15:14:06-2023-12-21- Не удалось получить id события > results_for_periods().Однако возникло исключение.
---------------------------------------------------------------------------------------------------------
Traceback (most recent call last):
  File "c:\Users\adamrv\Downloads\final-main\final-main\parser_string.py", line 17, in results_for_periods
    event = fact['event1']
KeyError: 'event1'


---------------------------------------------------------------------------------------------------------






---------------------------------------------------------------------------------------------------------
15:14:07-2023-12-21- Не удалось получить id события > results_for_periods().Однако возникло исключение.
---------------------------------------------------------------------------------------------------------
Traceback (most recent call last):
  File "c:\Users\adamrv\Downloads\final-main\final-main\parser_string.py", line 17, in results_for_periods
    event = fact['event1']
KeyError: 'event1'


---------------------------------------------------------------------------------------------------------






---------------------------------------------------------------------------------------------------------
15:14:07-2023-12-21- Не удалось получить id события > results_for_periods().Однако возникло исключение.
---------------------------------------------------------------------------------------------------------
Traceback (most recent call last):
  File "c:\Users\adamrv\Downloads\final-main\final-main\parser_string.py", line 17, in results_for_periods
    event = fact['event1']
KeyError: 'event1'


---------------------------------------------------------------------------------------------------------






---------------------------------------------------------------------------------------------------------
15:14:08-2023-12-21- Не удалось получить id события > results_for_periods().Однако возникло исключение.
---------------------------------------------------------------------------------------------------------
Traceback (most recent call last):
  File "c:\Users\adamrv\Downloads\final-main\final-main\parser_string.py", line 17, in results_for_periods
    event = fact['event1']
KeyError: 'event1'


---------------------------------------------------------------------------------------------------------






---------------------------------------------------------------------------------------------------------
15:14:08-2023-12-21- Не удалось получить id события > results_for_periods().Однако возникло исключение.
---------------------------------------------------------------------------------------------------------
Traceback (most recent call last):
  File "c:\Users\adamrv\Downloads\final-main\final-main\parser_string.py", line 17, in results_for_periods
    event = fact['event1']
KeyError: 'event1'


---------------------------------------------------------------------------------------------------------






---------------------------------------------------------------------------------------------------------
15:14:08-2023-12-21- Не удалось получить id события > results_for_periods().Однако возникло исключение.
---------------------------------------------------------------------------------------------------------
Traceback (most recent call last):
  File "c:\Users\adamrv\Downloads\final-main\final-main\parser_string.py", line 17, in results_for_periods
    event = fact['event1']
KeyError: 'event1'


---------------------------------------------------------------------------------------------------------






---------------------------------------------------------------------------------------------------------
15:14:09-2023-12-21- Не удалось получить id события > results_for_periods().Однако возникло исключение.
---------------------------------------------------------------------------------------------------------
Traceback (most recent call last):
  File "c:\Users\adamrv\Downloads\final-main\final-main\parser_string.py", line 17, in results_for_periods
    event = fact['event1']
KeyError: 'event1'


---------------------------------------------------------------------------------------------------------






---------------------------------------------------------------------------------------------------------
15:14:09-2023-12-21- Не удалось получить id события > results_for_periods().Однако возникло исключение.
---------------------------------------------------------------------------------------------------------
Traceback (most recent call last):
  File "c:\Users\adamrv\Downloads\final-main\final-main\parser_string.py", line 17, in results_for_periods
    event = fact['event1']
KeyError: 'event1'


---------------------------------------------------------------------------------------------------------






---------------------------------------------------------------------------------------------------------
15:14:10-2023-12-21- Не удалось получить id события > results_for_periods().Однако возникло исключение.
---------------------------------------------------------------------------------------------------------
Traceback (most recent call last):
  File "c:\Users\adamrv\Downloads\final-main\final-main\parser_string.py", line 17, in results_for_periods
    event = fact['event1']
KeyError: 'event1'


---------------------------------------------------------------------------------------------------------



